<?xml version="1.0" ?>
<!-- =================================================================================== -->
<!-- |    This document was autogenerated by xacro from ur5_robotiq_robot_limited.urdf.xacro | -->
<!-- |    EDITING THIS FILE BY HAND IS NOT RECOMMENDED                                 | -->
<!-- =================================================================================== -->
<robot name="ur5_robotiq85">
  <link name="world"/>
 <joint name="offset_joint" type="fixed">
    <parent link="world"/>
    <child link="base_link"/>
    <origin xyz="0.0 0.0 0.9144" rpy="0 0 1.57" />
 </joint>
  <link name="base_link">
    <visual>
      <geometry>
        <mesh filename="package://meshes/ur5/visual/base.dae"/>
      </geometry>
      <material name="LightGrey">
        <color rgba="0.7 0.7 0.7 1.0"/>
      </material>
    </visual>
    <collision>
      <geometry>
        <mesh filename="package://meshes/ur5/collision/base.stl"/>
      </geometry>
    </collision>
    <inertial>
      <mass value="4.0"/>
      <origin rpy="0 0 0" xyz="0.0 0.0 0.0"/>
      <inertia ixx="0.00443333156" ixy="0.0" ixz="0.0" iyy="0.00443333156" iyz="0.0" izz="0.0072"/>
    </inertial>
  </link>
  <joint name="shoulder_pan_joint" type="revolute">
    <parent link="base_link"/>
    <child link="shoulder_link"/>
    <origin rpy="0 0.0 0" xyz="0.0 0.0 0.089159"/>
    <axis xyz="0 0 1"/>
    <!-- <limit effort="150.0" lower="-3.14159265" upper="3.14159265" velocity="3.15"/> -->
    <limit effort="150.0" lower="-3.14159265" upper="3.14159265" velocity="0.5"/>
    <dynamics damping="0.0" friction="0.0"/>
  </joint>
  <link name="shoulder_link">
    <visual>
      <geometry>
        <mesh filename="package://meshes/ur5/visual/shoulder.dae"/>
      </geometry>
      <material name="LightGrey">
        <color rgba="0.7 0.7 0.7 1.0"/>
      </material>
    </visual>
    <collision>
      <geometry>
        <mesh filename="package://meshes/ur5/collision/shoulder.stl"/>
      </geometry>
    </collision>
    <inertial>
      <mass value="3.7"/>
      <origin rpy="0 0 0" xyz="0.0 0.0 0.0"/>
      <inertia ixx="0.010267495893" ixy="0.0" ixz="0.0" iyy="0.010267495893" iyz="0.0" izz="0.00666"/>
    </inertial>
  </link>
  <joint name="shoulder_lift_joint" type="revolute">
    <parent link="shoulder_link"/>
    <child link="upper_arm_link"/>
    <origin rpy="0.0 1.570796325 0.0" xyz="0.0 0.13585 0.0"/>
    <!--      <origin xyz="0.0 ${shoulder_offset} 0.0" rpy="0.0 ${angle_offset} 0.0" /> -->
    <axis xyz="0 1 0"/>
    <!-- <limit effort="150.0" lower="-3.14159265" upper="3.14159265" velocity="3.15"/> -->
    <limit effort="150.0" lower="-3.14159265" upper="3.14159265" velocity="0.5"/>
    <dynamics damping="0.0" friction="0.0"/>
  </joint>
  <link name="upper_arm_link">
    <visual>
      <geometry>
        <mesh filename="package://meshes/ur5/visual/upperarm.dae"/>
      </geometry>
      <material name="LightGrey">
        <color rgba="0.7 0.7 0.7 1.0"/>
      </material>
    </visual>
    <collision>
      <geometry>
        <mesh filename="package://meshes/ur5/collision/upperarm.stl"/>
      </geometry>
    </collision>
    <inertial>
      <mass value="8.393"/>
      <origin rpy="0 0 0" xyz="0.0 0.0 0.28"/>
      <inertia ixx="0.22689067591036005" ixy="0.0" ixz="0.0" iyy="0.22689067591036005" iyz="0.0" izz="0.0151074"/>
    </inertial>
  </link>
  <joint name="elbow_joint" type="revolute">
    <parent link="upper_arm_link"/>
    <child link="forearm_link"/>
    <origin rpy="0.0 0.0 0.0" xyz="0.0 -0.1197 0.425"/>
    <axis xyz="0 1 0"/>
    <!-- <limit effort="150.0" lower="-3.14159265" upper="3.14159265" velocity="3.15"/> -->
    <limit effort="150.0" lower="-3.14159265" upper="3.14159265" velocity="0.5"/>
    <dynamics damping="0.0" friction="0.0"/>
  </joint>
  <link name="forearm_link">
    <visual>
      <geometry>
        <mesh filename="package://meshes/ur5/visual/forearm.dae"/>
      </geometry>
      <material name="LightGrey">
        <color rgba="0.7 0.7 0.7 1.0"/>
      </material>
    </visual>
    <collision>
      <geometry>
        <mesh filename="package://meshes/ur5/collision/forearm.stl"/>
      </geometry>
    </collision>
    <inertial>
      <mass value="2.275"/>
      <origin rpy="0 0 0" xyz="0.0 0.0 0.25"/>
      <inertia ixx="0.04944331355599999" ixy="0.0" ixz="0.0" iyy="0.04944331355599999" iyz="0.0" izz="0.004095"/>
    </inertial>
  </link>
  <joint name="wrist_1_joint" type="revolute">
    <parent link="forearm_link"/>
    <child link="wrist_1_link"/>
    <origin rpy="0.0 1.570796325 0.0" xyz="0.0 0.0 0.39225"/>
    <axis xyz="0 1 0"/>
    <!-- <limit effort="28.0" lower="-3.14159265" upper="3.14159265" velocity="3.2"/> -->
    <limit effort="28.0" lower="-3.14159265" upper="3.14159265" velocity="0.5"/>
    <dynamics damping="0.0" friction="0.0"/>
  </joint>
  <link name="wrist_1_link">
    <visual>
      <geometry>
        <mesh filename="package://meshes/ur5/visual/wrist1.dae"/>
      </geometry>
      <material name="LightGrey">
        <color rgba="0.7 0.7 0.7 1.0"/>
      </material>
    </visual>
    <collision>
      <geometry>
        <mesh filename="package://meshes/ur5/collision/wrist1.stl"/>
      </geometry>
    </collision>
    <inertial>
      <mass value="1.219"/>
      <origin rpy="0 0 0" xyz="0.0 0.0 0.0"/>
      <inertia ixx="0.11117275553087999" ixy="0.0" ixz="0.0" iyy="0.11117275553087999" iyz="0.0" izz="0.21942"/>
    </inertial>
  </link>
  <joint name="wrist_2_joint" type="revolute">
    <parent link="wrist_1_link"/>
    <child link="wrist_2_link"/>
    <origin rpy="0.0 0.0 0.0" xyz="0.0 0.093 0.0"/>
    <axis xyz="0 0 1"/>
    <!-- <limit effort="28.0" lower="-3.14159265" upper="3.14159265" velocity="3.2"/> -->
    <limit effort="28.0" lower="-3.14159265" upper="3.14159265" velocity="0.5"/>
    <dynamics damping="0.0" friction="0.0"/>
  </joint>
  <link name="wrist_2_link">
    <visual>
      <geometry>
        <mesh filename="package://meshes/ur5/visual/wrist2.dae"/>
      </geometry>
      <material name="LightGrey">
        <color rgba="0.7 0.7 0.7 1.0"/>
      </material>
    </visual>
    <collision>
      <geometry>
        <mesh filename="package://meshes/ur5/collision/wrist2.stl"/>
      </geometry>
    </collision>
    <inertial>
      <mass value="1.219"/>
      <origin rpy="0 0 0" xyz="0.0 0.0 0.0"/>
      <inertia ixx="0.11117275553087999" ixy="0.0" ixz="0.0" iyy="0.11117275553087999" iyz="0.0" izz="0.21942"/>
    </inertial>
  </link>
  <joint name="wrist_3_joint" type="revolute">
    <parent link="wrist_2_link"/>
    <child link="wrist_3_link"/>
    <origin rpy="0.0 0.0 0.0" xyz="0.0 0.0 0.09465"/>
    <axis xyz="0 1 0"/>
    <!-- <limit effort="28.0" lower="-3.14159265" upper="3.14159265" velocity="3.2"/> -->
    <limit effort="28.0" lower="-3.14159265" upper="3.14159265" velocity="0.5"/>
    <dynamics damping="0.0" friction="0.0"/>
  </joint>
  <link name="wrist_3_link">
    <visual>
      <geometry>
        <mesh filename="package://meshes/ur5/visual/wrist3.dae"/>
      </geometry>
      <material name="LightGrey">
        <color rgba="0.7 0.7 0.7 1.0"/>
      </material>
    </visual>
    <collision>
      <geometry>
        <mesh filename="package://meshes/ur5/collision/wrist3.stl"/>
      </geometry>
    </collision>
    <inertial>
      <mass value="0.1879"/>
      <origin rpy="0 0 0" xyz="0.0 0.0 0.0"/>
      <inertia ixx="0.017136473145408" ixy="0.0" ixz="0.0" iyy="0.017136473145408" iyz="0.0" izz="0.033822"/>
    </inertial>
  </link>
  <joint name="ee_fixed_joint" type="fixed">
    <parent link="wrist_3_link"/>
    <child link="ee_link"/>
    <origin rpy="0.0 0.0 1.570796325" xyz="0.0 0.0823 0.0"/>
  </joint>
  <link name="ee_link">
    <collision>
      <geometry>
        <box size="0.01 0.01 0.01"/>
      </geometry>
      <origin rpy="0 0 0" xyz="-0.01 0 0"/>
    </collision>
  </link>
  <!-- mount the fts to the robot -->
  <joint name="fts_fix" type="fixed">
    <!--In most cases origin would be flange adapter plate: <origin xyz="0 0 0.009" rpy="0 0 0"/> /-->
    <origin rpy="0.0 0 -1.57" xyz="0.035 0 0.0"/>
    <parent link="ee_link"/>
    <child link="fts_robotside"/>
  </joint>
  <link name="fts_robotside">
    <inertial>
      <origin rpy="0 0 0" xyz="0 0 0.01875"/>
      <mass value="0.65"/>
      <inertia ixx="0.000661171875" ixy="0" ixz="0" iyy="0.000661171875" iyz="0" izz="0.00117"/>
    </inertial>
    <visual>
      <origin rpy="0 0 0" xyz="0 0 0"/>
      <geometry>
				<mesh filename="package://meshes/robotiq_fts300.stl"></mesh>
      </geometry>
      <material name="black"/>
    </visual>
    <collision>
      <origin rpy="0 0 0" xyz="0 0 0"/>
      <geometry>
				<mesh filename="package://meshes/robotiq_fts300.stl"></mesh>
      </geometry>
    </collision>
  </link>
  <link name="robotiq_85_base_link">
    <visual>
      <geometry>
				<mesh filename="package://meshes/robotiq/robotiq_85_base_link_fine.STL"></mesh>
      </geometry>
    </visual>
    <collision>
      <geometry>
				<mesh filename="package://meshes/robotiq/robotiq_85_base_link_fine.STL"></mesh>
      </geometry>
    </collision>
    <inertial>
      <origin xyz="0.0 2.274e-05 0.03232288" rpy="0 0 0" />
      <mass value="6.6320197e-01" />
      <inertia ixx="5.1617816e-04" iyy="5.8802208e-04" izz="3.9462776e-04" ixy="2.936e-8" ixz="0.0" iyz="-3.2296e-7" />
    </inertial>
  </link>
  <link name="robotiq_85_left_knuckle_link">
    <visual>
      <geometry>
				<mesh filename="meshes/robotiq/outer_knuckle_fine.STL"></mesh>
      </geometry>
    </visual>
    <collision>
      <geometry>
				<mesh filename="meshes/robotiq/outer_knuckle_fine.STL"></mesh>
      </geometry>
    </collision>
    <inertial>
      <origin xyz="0.01213197 0.0002 -0.00058647" rpy="0 0 0" />
      <mass value="1.384773208e-02" />
      <inertia ixx="3.5232e-7" iyy="2.31944e-6" izz="2.23136e-6" ixy="0.0" ixz="1.1744e-7" iyz="0" />
    </inertial>
  </link>
  <link name="robotiq_85_right_knuckle_link">
    <visual>
      <geometry>
				<mesh filename="meshes/robotiq/outer_knuckle_fine.STL"></mesh>
      </geometry>
    </visual>
    <collision>
      <geometry>
				<mesh filename="meshes/robotiq/outer_knuckle_fine.STL"></mesh>
      </geometry>
    </collision>
    <inertial>
      <origin xyz="-0.01213197 0.0002 -0.00058647" rpy="0 0 0" />
      <mass value="1.384773208e-02" />
      <inertia ixx="3.5232e-7" iyy="2.31944e-6" izz="2.23136e-6" ixy="0.0" ixz="-1.1744e-7" iyz="0.0" />
    </inertial>
  </link>
  <link name="robotiq_85_left_finger_link">
    <visual>
      <geometry>
				<mesh filename="meshes/robotiq/outer_finger_fine.STL"></mesh>
      </geometry>
    </visual>
    <collision>
      <geometry>
				<mesh filename="meshes/robotiq/outer_finger_fine.STL"></mesh>
      </geometry>
    </collision>
    <inertial>
      <origin xyz="0.00346899 -0.00079447 0.01867121" rpy="0 0 0" />
      <mass value="4.260376752e-02" />
      <inertia ixx="1.385792000000000e-05" iyy="1.183208e-05" izz="5.19672e-06" ixy="0.0" ixz="-2.17264e-06" iyz="0.0" />
    </inertial>
  </link>
  <link name="robotiq_85_right_finger_link">
    <visual>
      <geometry>
				<mesh filename="meshes/robotiq/outer_finger_fine.STL"></mesh>
      </geometry>
    </visual>
    <collision>
      <geometry>
				<mesh filename="meshes/robotiq/outer_finger_fine.STL"></mesh>
      </geometry>
    </collision>
    <inertial>
      <origin xyz="-0.00346899 -5.53e-06 0.01867121" rpy="0 0 0" />
      <mass value="4.260376752000000e-02" />
      <inertia ixx="1.385792e-05" iyy="1.183208e-05" izz="5.19672e-06" ixy="0.0" ixz="2.17264e-06" iyz="0.0" />
    </inertial>
  </link>
  <link name="robotiq_85_left_inner_knuckle_link">
    <visual>
      <geometry>
				<mesh filename="meshes/robotiq/inner_knuckle_fine.STL"></mesh>
      </geometry>
    </visual>
    <collision>
      <geometry>
				<mesh filename="meshes/robotiq/inner_knuckle_fine.STL"></mesh>
      </geometry>
    </collision>
    <inertial>
      <origin xyz="0.01897699 0.00015001 0.02247101" rpy="0 0 0" />
      <mass value="2.969376448e-02" />
      <inertia ixx="9.57136e-06" iyy="8.69056e-06" izz="8.19144e-06" ixy="0.0" ixz="-3.93424e-06" iyz="0.0" />
    </inertial>
  </link>
  <link name="robotiq_85_right_inner_knuckle_link">
    <visual>
      <geometry>
				<mesh filename="meshes/robotiq/inner_knuckle_fine.STL"></mesh>
      </geometry>
    </visual>
    <collision>
      <geometry>
				<mesh filename="meshes/robotiq/inner_knuckle_fine.STL"></mesh>
      </geometry>
    </collision>
    <inertial>
      <origin xyz="-0.01926824 5.001e-05 0.02222178" rpy="0 0 0" />
      <mass value="2.969376448e-02" />
      <inertia ixx="9.42456e-06" iyy="8.69056e-06" izz="8.33824e-06" ixy="0.0" ixz="3.9636e-06" iyz="0.0" />
    </inertial>
  </link>
  <link name="robotiq_85_left_finger_tip_link">
    <visual>
      <geometry>
				<mesh filename="meshes/robotiq/inner_finger_fine.STL"></mesh>
      </geometry>
    </visual>
    <collision>
      <geometry>
				<mesh filename="meshes/robotiq/inner_finger_fine.STL"></mesh>
      </geometry>
    </collision>
    <inertial>
      <origin xyz="-0.01456706 -0.0008 0.01649701" rpy="0 0 0" />
      <mass value="4.268588744e-02" />
      <inertia ixx="1.048152e-05" iyy="1.197888e-05" izz="4.22784e-06" ixy="0.0" ixz="3.5232e-6" iyz="0.0" />
    </inertial>
  </link>
  <link name="robotiq_85_right_finger_tip_link">
    <visual>
      <geometry>
				<mesh filename="meshes/robotiq/inner_finger_fine.STL"></mesh>
      </geometry>
    </visual>
    <collision>
      <geometry>
				<mesh filename="meshes/robotiq/inner_finger_fine.STL"></mesh>
      </geometry>
    </collision>
    <inertial>
        <origin xyz="0.01456706 5e-05 0.01649701" rpy="0 0 0" />
        <mass value="4.268588744e-02" />
        <inertia ixx="1.048152e-05" iyy="1.197888e-05" izz="4.22784e-06" ixy="0.0" ixz="-3.5232e-06" iyz="0.0" />
    </inertial>
  </link>
	<joint name="robotiq_85_base_joint" type="fixed">
		<parent link="fts_robotside"></parent>
		<child link="robotiq_85_base_link"></child>
		<origin rpy="-1.57 0.0 0.0" xyz="0.0 0.0 -0.037"></origin>
	</joint>
	<joint name="robotiq_85_left_knuckle_joint" type="fixed">
		<origin xyz="0.0306011444260539 0 0.0627920162695395" rpy="0 0 0"></origin>
		<parent link="robotiq_85_base_link"></parent>
		<child link="robotiq_85_left_knuckle_link"></child>
		<axis xyz="0 -1 0"></axis>
	</joint>
	<joint name="robotiq_85_left_finger_joint" type="fixed">
		<origin xyz="0.0316910442266543 0 -0.00193396375724605" rpy="0 0 0"></origin>
		<parent link="robotiq_85_left_knuckle_link"></parent>
		<child link="robotiq_85_left_finger_link"></child>
		<axis xyz="0 -1 0"></axis>
	</joint>
	<joint name="robotiq_85_left_inner_knuckle_joint" type="fixed">
		<origin xyz="0.0127000000001501 0 0.0693074999999639" rpy="0 0 0"></origin>
		<parent link="robotiq_85_base_link"></parent>
		<child link="robotiq_85_left_inner_knuckle_link"></child>
		<axis xyz="0 -1 0"></axis>
	</joint>
	<joint name="robotiq_85_left_finger_tip_joint" type="fixed">
		<origin xyz="0.034585310861294 0 0.0454970193817975" rpy="0 0 0"></origin>
		<parent link="robotiq_85_left_inner_knuckle_link"></parent>
		<child link="robotiq_85_left_finger_tip_link"></child>
		<axis xyz="0 -1 0"></axis>
	</joint>
	<joint name="robotiq_85_right_inner_knuckle_joint" type="fixed">
		<origin xyz="-0.0126999999998499 0 0.0693075000000361" rpy="0 0 3.14159265358979"></origin>
		<parent link="robotiq_85_base_link"></parent>
		<child link="robotiq_85_right_inner_knuckle_link"></child>
		<axis xyz="0 1 0"></axis>
	</joint>
	<joint name="robotiq_85_right_finger_tip_joint" type="fixed">
		<origin xyz="0.0341060475457406 0 0.0458573878541688" rpy="0 0 0"></origin>
		<parent link="robotiq_85_right_inner_knuckle_link"></parent>
		<child link="robotiq_85_right_finger_tip_link"></child>
		<axis xyz="0 1 0"></axis>
	</joint>
	<joint name="robotiq_85_right_knuckle_joint" type="fixed">
		<origin xyz="-0.0306011444258893 0 0.0627920162695395" rpy="0 0 3.14159265358979"></origin>
		<parent link="robotiq_85_base_link"></parent>
		<child link="robotiq_85_right_knuckle_link"></child>
		<axis xyz="0 1 0"></axis>
	</joint>
	<joint name="robotiq_85_right_finger_joint" type="fixed">
		<origin xyz="0.0317095909367246 0 -0.0016013564954687" rpy="0 0 0"></origin>
		<parent link="robotiq_85_right_knuckle_link"></parent>
		<child link="robotiq_85_right_finger_link"></child>
		<axis xyz="0 1 0"></axis>
	</joint>
</robot>

